<?xml version="1.0"?>
<robot xmlns:xacro="http://www.ros.org/wiki/xacro" name="mobile_base">

  <!-- Dimensions and parameters -->
  <xacro:property name="BASE_LENGTH" value="0.8"/>   <!-- body length (x) -->
  <xacro:property name="BASE_WIDTH"  value="0.6"/>   <!-- body width (y) -->
  <xacro:property name="BASE_HEIGHT" value="0.15"/>  <!-- body height (z) -->
  <xacro:property name="WHEEL_RADIUS" value="0.1"/>
  <xacro:property name="WHEEL_THICK"  value="0.05"/>
  <xacro:property name="CLEARANCE"    value="0.02"/> <!-- ground clearance -->

  <!-- Control parameters -->
  <xacro:property name="WHEEL_SEPARATION" value="${BASE_WIDTH}"/>
  <xacro:property name="WHEEL_BASE"       value="${BASE_LENGTH * 0.8}"/>

  <!-- Mass properties -->
  <xacro:property name="M_BASE"  value="20.0"/>
  <xacro:property name="M_WHEEL" value="2.0"/>

  <!-- Inertia calculations -->
  <!-- Box: Ixx = 1/12 m (y^2 + z^2), etc. -->
  <xacro:property name="Ixx_base" value="${(M_BASE/12.0) * (BASE_WIDTH*BASE_WIDTH + BASE_HEIGHT*BASE_HEIGHT)}"/>
  <xacro:property name="Iyy_base" value="${(M_BASE/12.0) * (BASE_LENGTH*BASE_LENGTH + BASE_HEIGHT*BASE_HEIGHT)}"/>
  <xacro:property name="Izz_base" value="${(M_BASE/12.0) * (BASE_LENGTH*BASE_LENGTH + BASE_WIDTH*BASE_WIDTH)}"/>

  <!-- Cylinder wheel: Ixx=Iyy=1/12 m (3r^2 + L^2), Izz=1/2 m r^2 -->
  <xacro:property name="Ixx_w" value="${(M_WHEEL/12.0) * (3*WHEEL_RADIUS*WHEEL_RADIUS + WHEEL_THICK*WHEEL_THICK)}"/>
  <xacro:property name="Iyy_w" value="${(M_WHEEL/2.0)  * (WHEEL_RADIUS*WHEEL_RADIUS)}"/>
  <xacro:property name="Izz_w" value="${(M_WHEEL/12.0) * (3*WHEEL_RADIUS*WHEEL_RADIUS + WHEEL_THICK*WHEEL_THICK)}"/>

  <xacro:macro name="base_vehicle" params="">

    <!-- Standard floor frame -->
    <link name="base_footprint"/>
    <joint name="base_footprint_joint" type="fixed">
      <parent link="base_footprint"/>
      <child  link="base_link"/>
      <origin xyz="0 0 ${BASE_HEIGHT/2 + CLEARANCE}" rpy="0 0 0"/>
    </joint>

    <!-- Vehicle body -->
    <link name="base_link">
      <inertial>
        <origin xyz="0 0 ${BASE_HEIGHT/2}" rpy="0 0 0"/>
        <mass value="${M_BASE}"/>
        <inertia ixx="${Ixx_base}" iyy="${Iyy_base}" izz="${Izz_base}" ixy="0" ixz="0" iyz="0"/>
      </inertial>

      <visual>
        <origin xyz="0 0 ${BASE_HEIGHT/2}" rpy="0 0 0"/>
        <geometry>
          <box size="${BASE_LENGTH} ${BASE_WIDTH} ${BASE_HEIGHT}"/>
        </geometry>
        <material name="base_grey"><color rgba="0.6 0.6 0.6 1"/></material>
      </visual>

      <collision>
        <origin xyz="0 0 ${BASE_HEIGHT/2}" rpy="0 0 0"/>
        <geometry>
          <box size="${BASE_LENGTH} ${BASE_WIDTH} ${BASE_HEIGHT}"/>
        </geometry>
        <surface>
          <friction>
            <ode>
              <mu>0.8</mu>
              <mu2>0.8</mu2>
            </ode>
          </friction>
        </surface>
      </collision>
    </link>

    <!-- Left wheel -->
    <link name="left_wheel_link">
      <inertial>
        <origin xyz="0 0 0" rpy="0 0 0"/>
        <mass value="${M_WHEEL}"/>
        <inertia ixx="${Ixx_w}" iyy="${Iyy_w}" izz="${Izz_w}" ixy="0" ixz="0" iyz="0"/>
      </inertial>

      <visual>
        <!-- Rotate around X axis 90° to align cylinder axis (z) with y axis (wheel rotation axis) -->
        <origin xyz="0 0 0" rpy="1.5708 0 0"/>
        <geometry>
          <cylinder radius="${WHEEL_RADIUS}" length="${WHEEL_THICK}"/>
        </geometry>
        <material name="wheel_black"><color rgba="0.1 0.1 0.1 1"/></material>
      </visual>

      <collision>
        <origin xyz="0 0 0" rpy="1.5708 0 0"/>
        <geometry>
          <cylinder radius="${WHEEL_RADIUS}" length="${WHEEL_THICK}"/>
        </geometry>
        <surface>
          <friction>
            <ode>
              <mu>1.2</mu>
              <mu2>1.2</mu2>
            </ode>
          </friction>
        </surface>
      </collision>
    </link>

    <!-- Right wheel (mirror) -->
    <link name="right_wheel_link">
      <inertial>
        <origin xyz="0 0 0" rpy="0 0 0"/>
        <mass value="${M_WHEEL}"/>
        <inertia ixx="${Ixx_w}" iyy="${Iyy_w}" izz="${Izz_w}" ixy="0" ixz="0" iyz="0"/>
      </inertial>

      <visual>
        <origin xyz="0 0 0" rpy="1.5708 0 0"/>
        <geometry>
          <cylinder radius="${WHEEL_RADIUS}" length="${WHEEL_THICK}"/>
        </geometry>
        <material name="wheel_black"/>
      </visual>

      <collision>
        <origin xyz="0 0 0" rpy="1.5708 0 0"/>
        <geometry>
          <cylinder radius="${WHEEL_RADIUS}" length="${WHEEL_THICK}"/>
        </geometry>
        <surface>
          <friction>
            <ode>
              <mu>1.2</mu>
              <mu2>1.2</mu2>
            </ode>
          </friction>
        </surface>
      </collision>
    </link>

    <!-- Wheel joints: rotation axis along y -->
    <joint name="left_wheel_joint" type="continuous">
      <parent link="base_link"/>
      <child  link="left_wheel_link"/>
      <origin xyz="0 ${BASE_WIDTH/2} ${WHEEL_RADIUS + CLEARANCE}" rpy="0 0 0"/>
      <axis xyz="0 1 0"/>
      <limit effort="10" velocity="20"/>
      <dynamics damping="0.2" friction="0.0"/>
    </joint>

    <joint name="right_wheel_joint" type="continuous">
      <parent link="base_link"/>
      <child  link="right_wheel_link"/>
      <origin xyz="0 -${BASE_WIDTH/2} ${WHEEL_RADIUS + CLEARANCE}" rpy="0 0 0"/>
      <axis xyz="0 1 0"/>
      <limit effort="10" velocity="20"/>
      <dynamics damping="0.2" friction="0.0"/>
    </joint>

  </xacro:macro>
</robot>